2024-04-05 22:02:02,953 INFO    MainThread:52888 [internal.py:wandb_internal():90] W&B internal server running at pid: 52888, started at: 2024-04-05 22:02:02.953235
2024-04-05 22:02:02,954 INFO    WriterThread:52888 [datastore.py:open_for_write():75] open: /Users/ayushshekhar/Desktop/work/ml/Master/src/wandb/run-20240405_220202-1d98q13f/run-1d98q13f.wandb
2024-04-05 22:02:02,954 DEBUG   SenderThread:52888 [sender.py:send():232] send: header
2024-04-05 22:02:02,955 DEBUG   SenderThread:52888 [sender.py:send():232] send: run
2024-04-05 22:02:03,123 ERROR   SenderThread:52888 [internal_api.py:execute():143] 403 response executing GraphQL.
2024-04-05 22:02:03,123 ERROR   SenderThread:52888 [internal_api.py:execute():144] {"errors":[{"message":"permission denied","path":["upsertBucket"],"extensions":{"code":"PERMISSION_ERROR"}}],"data":{"upsertBucket":null}}
2024-04-05 22:02:03,955 INFO    HandlerThread:52888 [handler.py:finish():806] shutting down handler
2024-04-05 22:02:03,957 INFO    WriterThread:52888 [datastore.py:close():279] close: /Users/ayushshekhar/Desktop/work/ml/Master/src/wandb/run-20240405_220202-1d98q13f/run-1d98q13f.wandb
2024-04-05 22:02:03,959 ERROR   MainThread:52888 [internal.py:wandb_internal():165] Thread SenderThread:
Traceback (most recent call last):
  File "/Users/ayushshekhar/anaconda3/envs/py3.9/lib/python3.9/site-packages/wandb/sdk/lib/retry.py", line 102, in __call__
    result = self._call_fn(*args, **kwargs)
  File "/Users/ayushshekhar/anaconda3/envs/py3.9/lib/python3.9/site-packages/wandb/sdk/internal/internal_api.py", line 140, in execute
    return self.client.execute(*args, **kwargs)
  File "/Users/ayushshekhar/anaconda3/envs/py3.9/lib/python3.9/site-packages/wandb/vendor/gql-0.2.0/wandb_gql/client.py", line 52, in execute
    result = self._get_result(document, *args, **kwargs)
  File "/Users/ayushshekhar/anaconda3/envs/py3.9/lib/python3.9/site-packages/wandb/vendor/gql-0.2.0/wandb_gql/client.py", line 60, in _get_result
    return self.transport.execute(document, *args, **kwargs)
  File "/Users/ayushshekhar/anaconda3/envs/py3.9/lib/python3.9/site-packages/wandb/vendor/gql-0.2.0/wandb_gql/transport/requests.py", line 39, in execute
    request.raise_for_status()
  File "/Users/ayushshekhar/anaconda3/envs/py3.9/lib/python3.9/site-packages/requests/models.py", line 960, in raise_for_status
    raise HTTPError(http_error_msg, response=self)
requests.exceptions.HTTPError: 403 Client Error: Forbidden for url: https://api.wandb.ai/graphql

During handling of the above exception, another exception occurred:

Traceback (most recent call last):
  File "/Users/ayushshekhar/anaconda3/envs/py3.9/lib/python3.9/site-packages/wandb/apis/normalize.py", line 22, in wrapper
    return func(*args, **kwargs)
  File "/Users/ayushshekhar/anaconda3/envs/py3.9/lib/python3.9/site-packages/wandb/sdk/internal/internal_api.py", line 1319, in upsert_run
    response = self.gql(mutation, variable_values=variable_values, **kwargs)
  File "/Users/ayushshekhar/anaconda3/envs/py3.9/lib/python3.9/site-packages/wandb/sdk/lib/retry.py", line 118, in __call__
    if not check_retry_fn(e):
  File "/Users/ayushshekhar/anaconda3/envs/py3.9/lib/python3.9/site-packages/wandb/util.py", line 882, in no_retry_auth
    raise CommError("Permission denied, ask the project owner to grant you access")
wandb.errors.CommError: Permission denied, ask the project owner to grant you access

During handling of the above exception, another exception occurred:

Traceback (most recent call last):
  File "/Users/ayushshekhar/anaconda3/envs/py3.9/lib/python3.9/site-packages/wandb/sdk/internal/internal_util.py", line 51, in run
    self._run()
  File "/Users/ayushshekhar/anaconda3/envs/py3.9/lib/python3.9/site-packages/wandb/sdk/internal/internal_util.py", line 102, in _run
    self._process(record)
  File "/Users/ayushshekhar/anaconda3/envs/py3.9/lib/python3.9/site-packages/wandb/sdk/internal/internal.py", line 310, in _process
    self._sm.send(record)
  File "/Users/ayushshekhar/anaconda3/envs/py3.9/lib/python3.9/site-packages/wandb/sdk/internal/sender.py", line 234, in send
    send_handler(record)
  File "/Users/ayushshekhar/anaconda3/envs/py3.9/lib/python3.9/site-packages/wandb/sdk/internal/sender.py", line 692, in send_run
    self._init_run(run, config_value_dict)
  File "/Users/ayushshekhar/anaconda3/envs/py3.9/lib/python3.9/site-packages/wandb/sdk/internal/sender.py", line 716, in _init_run
    server_run, inserted = self._api.upsert_run(
  File "/Users/ayushshekhar/anaconda3/envs/py3.9/lib/python3.9/site-packages/wandb/apis/normalize.py", line 58, in wrapper
    raise CommError(message, err).with_traceback(sys.exc_info()[2])
  File "/Users/ayushshekhar/anaconda3/envs/py3.9/lib/python3.9/site-packages/wandb/apis/normalize.py", line 22, in wrapper
    return func(*args, **kwargs)
  File "/Users/ayushshekhar/anaconda3/envs/py3.9/lib/python3.9/site-packages/wandb/sdk/internal/internal_api.py", line 1319, in upsert_run
    response = self.gql(mutation, variable_values=variable_values, **kwargs)
  File "/Users/ayushshekhar/anaconda3/envs/py3.9/lib/python3.9/site-packages/wandb/sdk/lib/retry.py", line 118, in __call__
    if not check_retry_fn(e):
  File "/Users/ayushshekhar/anaconda3/envs/py3.9/lib/python3.9/site-packages/wandb/util.py", line 882, in no_retry_auth
    raise CommError("Permission denied, ask the project owner to grant you access")
wandb.errors.CommError: Permission denied, ask the project owner to grant you access
2024-04-05 22:02:05,978 INFO    MainThread:52888 [internal.py:handle_exit():80] Internal process exited
